<?xml version="1.0" encoding="UTF-8"?>
<!-- Generated by org.testng.reporters.JUnitReportReporter -->
<testsuite hostname="wgybzb" name="zx.soft.utils.concurrent.Issue5" tests="2" failures="2" timestamp="17 Sep 2015 06:49:33 GMT" time="0.011" errors="0">
  <testcase name="testTwo" time="0.001" classname="zx.soft.utils.concurrent.Issue5">
    <failure type="org.testng.TestException" message="
Expected exception java.lang.AssertionError but got org.testng.TestException: 
Method Issue5.testTwo()[pri:0, instance:zx.soft.utils.concurrent.Issue5@483bf400] should have thrown an exception of class java.lang.AssertionError">
      <![CDATA[org.testng.TestException: 
Expected exception java.lang.AssertionError but got org.testng.TestException: 
Method Issue5.testTwo()[pri:0, instance:zx.soft.utils.concurrent.Issue5@483bf400] should have thrown an exception of class java.lang.AssertionError
	at org.testng.internal.Invoker.handleInvocationResults(Invoker.java:1485)
	at org.testng.internal.Invoker.invokeTestMethods(Invoker.java:1233)
	at org.testng.internal.TestMethodWorker.invokeTestMethods(TestMethodWorker.java:127)
	at org.testng.internal.TestMethodWorker.run(TestMethodWorker.java:111)
	at org.testng.TestRunner.privateRun(TestRunner.java:768)
	at org.testng.TestRunner.run(TestRunner.java:617)
	at org.testng.SuiteRunner.runTest(SuiteRunner.java:334)
	at org.testng.SuiteRunner.runSequentially(SuiteRunner.java:329)
	at org.testng.SuiteRunner.privateRun(SuiteRunner.java:291)
	at org.testng.SuiteRunner.run(SuiteRunner.java:240)
	at org.testng.SuiteRunnerWorker.runSuite(SuiteRunnerWorker.java:53)
	at org.testng.SuiteRunnerWorker.run(SuiteRunnerWorker.java:87)
	at org.testng.TestNG.runSuitesSequentially(TestNG.java:1188)
	at org.testng.TestNG.runSuitesLocally(TestNG.java:1113)
	at org.testng.TestNG.run(TestNG.java:1025)
	at org.testng.remote.RemoteTestNG.run(RemoteTestNG.java:109)
	at org.testng.remote.RemoteTestNG.initAndRun(RemoteTestNG.java:202)
	at org.testng.remote.RemoteTestNG.main(RemoteTestNG.java:173)
Caused by: org.testng.TestException: 
Method Issue5.testTwo()[pri:0, instance:zx.soft.utils.concurrent.Issue5@483bf400] should have thrown an exception of class java.lang.AssertionError
	at org.testng.internal.Invoker.handleInvocationResults(Invoker.java:1500)
	at org.testng.internal.Invoker.invokeMethod(Invoker.java:751)
	at org.testng.internal.Invoker.invokeTestMethod(Invoker.java:894)
	at org.testng.internal.Invoker.invokeTestMethods(Invoker.java:1219)
	... 16 more
]]>
    </failure>
  </testcase> <!-- testTwo -->
  <testcase name="testOne" time="0.010" classname="zx.soft.utils.concurrent.Issue5">
    <failure type="org.testng.TestException" message="
Expected exception java.lang.AssertionError but got org.testng.TestException: 
Method Issue5.testOne()[pri:0, instance:zx.soft.utils.concurrent.Issue5@483bf400] should have thrown an exception of class java.lang.AssertionError">
      <![CDATA[org.testng.TestException: 
Expected exception java.lang.AssertionError but got org.testng.TestException: 
Method Issue5.testOne()[pri:0, instance:zx.soft.utils.concurrent.Issue5@483bf400] should have thrown an exception of class java.lang.AssertionError
	at org.testng.internal.Invoker.handleInvocationResults(Invoker.java:1485)
	at org.testng.internal.Invoker.invokeTestMethods(Invoker.java:1233)
	at org.testng.internal.TestMethodWorker.invokeTestMethods(TestMethodWorker.java:127)
	at org.testng.internal.TestMethodWorker.run(TestMethodWorker.java:111)
	at org.testng.TestRunner.privateRun(TestRunner.java:768)
	at org.testng.TestRunner.run(TestRunner.java:617)
	at org.testng.SuiteRunner.runTest(SuiteRunner.java:334)
	at org.testng.SuiteRunner.runSequentially(SuiteRunner.java:329)
	at org.testng.SuiteRunner.privateRun(SuiteRunner.java:291)
	at org.testng.SuiteRunner.run(SuiteRunner.java:240)
	at org.testng.SuiteRunnerWorker.runSuite(SuiteRunnerWorker.java:53)
	at org.testng.SuiteRunnerWorker.run(SuiteRunnerWorker.java:87)
	at org.testng.TestNG.runSuitesSequentially(TestNG.java:1188)
	at org.testng.TestNG.runSuitesLocally(TestNG.java:1113)
	at org.testng.TestNG.run(TestNG.java:1025)
	at org.testng.remote.RemoteTestNG.run(RemoteTestNG.java:109)
	at org.testng.remote.RemoteTestNG.initAndRun(RemoteTestNG.java:202)
	at org.testng.remote.RemoteTestNG.main(RemoteTestNG.java:173)
Caused by: org.testng.TestException: 
Method Issue5.testOne()[pri:0, instance:zx.soft.utils.concurrent.Issue5@483bf400] should have thrown an exception of class java.lang.AssertionError
	at org.testng.internal.Invoker.handleInvocationResults(Invoker.java:1500)
	at org.testng.internal.Invoker.invokeMethod(Invoker.java:751)
	at org.testng.internal.Invoker.invokeTestMethod(Invoker.java:894)
	at org.testng.internal.Invoker.invokeTestMethods(Invoker.java:1219)
	... 16 more
]]>
    </failure>
  </testcase> <!-- testOne -->
</testsuite> <!-- zx.soft.utils.concurrent.Issue5 -->
